Workbook

Sheet New
A1: THUMB | B1: NEW | C1: NOME | D1: DOODSTREAM | E1: LULUSTREAM | G1: DOOD | H1: NOME | I1: SITE | J1: TITLE | K1: ID | L1: # | M1: POST | O1: Images | P1: Source
A2: Abbie Sykes - 99599676 - ripnsfw.com.jpg | B2: {New} | C2: =LEFT(A2,FIND("-",A2)-1) -> Abbie Sykes | D2: https://doodstream.com/d/iwq3xu4r8tsg/ | E2: https://lulustream.com/d/tkl7lny2e6ta | F2: =IFERROR(__xludf.DUMMYFUNCTION("""https://streamtape.com/v/""& REGEXEXTRACT(O2,""/thumb/([^/]+)/"")& ""/""&K2"),"https://streamtape.com/v/yPdwROL8ZwH3Qa/99599676") -> https://streamtape.com/v/yPdwROL8ZwH3Qa/99599676 | G2: =_xludf.CONCAT(D2,K2) -> #NAME? | H2: =IFERROR(__xludf.DUMMYFUNCTION("IFERROR(SUBSTITUTE(SUBSTITUTE(REGEXEXTRACT(A2, ""[^-]+- [^-]+- [^-]+ - (.+?)\.jpg""), "".jpg"", """"), ""-"", "", ""), """")"),"") | J2: =IF(B2="{New}", "(" & YEAR(TODAY()) & ")", "") -> (2026) | K2: =MID(A2,FIND("-",A2)+2,8) -> 99599676 | L2: #Hardcore, #Threesome, #Bigass, #Teen, #Blowjob, #Amateur, #Blonde, #Facial | M2: =IFERROR(__xludf.DUMMYFUNCTION("TRIM( REGEXREPLACE( TEXTJOIN("" "", TRUE, B2, C2, embaralharLinks(E2,F2,G2), H2, """", J2, N2, ""#RIPNSFW"" ), "",\s*"", "" "") )"),"{New} Abbie Sykes https://lulustream.com/d/tkl7lny2e6ta https://streamtape.com/v/yPdwROL8ZwH3Qa/99599676 https://doodstream.com/d/iwq3xu4r8tsg/99599676 (2026) #Hardcore #Threesome #Bigass #Teen #RIPNSFW") -> {New} Abbie Sykes https://lulustream.com/d/tkl7lny2e6ta https://streamtape.com/v/yPdwROL8ZwH3Qa/99599676 https://doodstream.com/d/iwq3xu4r8tsg/99599676 (2026) #Hardcore #Threesome #Bigass #Teen #RIPNSFW | N2: #Hardcore #Threesome #Bigass #Teen | O2: https://thumb.tapecontent.net/thumb/yPdwROL8ZwH3Qa/LaR0Vrr7jzsRqPA.jpg
A3: Abigaiil Morris - 33943707 - ripnsfw.com.jpg | B3: {New} | C3: =LEFT(A3,FIND("-",A3)-1) -> Abigaiil Morris | D3: https://doodstream.com/d/s5upwfgb0e1n/ | E3: https://lulustream.com/d/hodrrnuyu917 | F3: =IFERROR(__xludf.DUMMYFUNCTION("""https://streamtape.com/v/""& REGEXEXTRACT(O3,""/thumb/([^/]+)/"")& ""/""&K3"),"https://streamtape.com/v/BJ3Gj7o3lkcyZb6/33943707") -> https://streamtape.com/v/BJ3Gj7o3lkcyZb6/33943707 | G3: =_xludf.CONCAT(D3,K3) -> #NAME? | H3: =IFERROR(__xludf.DUMMYFUNCTION("IFERROR(SUBSTITUTE(SUBSTITUTE(REGEXEXTRACT(A3, ""[^-]+- [^-]+- [^-]+ - (.+?)\.jpg""), "".jpg"", """"), ""-"", "", ""), """")"),"") | J3: =IF(B3="{New}", "(" & YEAR(TODAY()) & ")", "") -> (2026) | K3: =MID(A3,FIND("-",A3)+2,8) -> 33943707 | L3: #BigTits, #Creampie, #Hardcore, #Bigass, #Teen, #Blowjob, #Amateur | M3: =IFERROR(__xludf.DUMMYFUNCTION("TRIM( REGEXREPLACE( TEXTJOIN("" "", TRUE, B3, C3, embaralharLinks(E3,F3,G3), H3, """", J3, N3, ""#RIPNSFW"" ), "",\s*"", "" "") )"),"{New} Abigaiil Morris https://doodstream.com/d/s5upwfgb0e1n/33943707 https://lulustream.com/d/hodrrnuyu917 https://streamtape.com/v/BJ3Gj7o3lkcyZb6/33943707 (2026) #BigTits #Creampie #Hardcore #Bigass #Teen #Blowjob #RIPNSFW") -> {New} Abigaiil Morris https://doodstream.com/d/s5upwfgb0e1n/33943707 https://lulustream.com/d/hodrrnuyu917 https://streamtape.com/v/BJ3Gj7o3lkcyZb6/33943707 (2026) #BigTits #Creampie #Hardcore #Bigass #Teen #Blowjob #RIPNSFW | N3: #BigTits #Creampie #Hardcore #Bigass #Teen #Blowjob | O3: https://thumb.tapecontent.net/thumb/BJ3Gj7o3lkcyZb6/69oK4xX1LvF9wq3.jpg
A4: Abigaiil Morris - 91692587 - ripnsfw.com.jpg | B4: {New} | C4: =LEFT(A4,FIND("-",A4)-1) -> Abigaiil Morris | D4: https://doodstream.com/d/b3z64gcsi3ef/ | E4: https://lulustream.com/d/blm3qsuunjcw | F4: =IFERROR(__xludf.DUMMYFUNCTION("""https://streamtape.com/v/""& REGEXEXTRACT(O4,""/thumb/([^/]+)/"")& ""/""&K4"),"https://streamtape.com/v/vxMBoKwORPCJpO/91692587") -> https://streamtape.com/v/vxMBoKwORPCJpO/91692587 | G4: =_xludf.CONCAT(D4,K4) -> #NAME? | H4: =IFERROR(__xludf.DUMMYFUNCTION("IFERROR(SUBSTITUTE(SUBSTITUTE(REGEXEXTRACT(A4, ""[^-]+- [^-]+- [^-]+ - (.+?)\.jpg""), "".jpg"", """"), ""-"", "", ""), """")"),"") | J4: =IF(B4="{New}", "(" & YEAR(TODAY()) & ")", "") -> (2026) | K4: =MID(A4,FIND("-",A4)+2,8) -> 91692587 | L4: #BigTits, #Black, #Interracial, #Bigass, #Teen, #Blowjob, #Amateur, #Deepthroat, #Facial | M4: =IFERROR(__xludf.DUMMYFUNCTION("TRIM( REGEXREPLACE( TEXTJOIN("" "", TRUE, B4, C4, embaralharLinks(E4,F4,G4), H4, """", J4, N4, ""#RIPNSFW"" ), "",\s*"", "" "") )"),"{New} Abigaiil Morris https://streamtape.com/v/vxMBoKwORPCJpO/91692587 https://lulustream.com/d/blm3qsuunjcw https://doodstream.com/d/b3z64gcsi3ef/91692587 (2026) #BigTits #Black #Interracial #Bigass #Teen #Blowjob #RIPNSFW") -> {New} Abigaiil Morris https://streamtape.com/v/vxMBoKwORPCJpO/91692587 https://lulustream.com/d/blm3qsuunjcw https://doodstream.com/d/b3z64gcsi3ef/91692587 (2026) #BigTits #Black #Interracial #Bigass #Teen #Blowjob #RIPNSFW | N4: #BigTits #Black #Interracial #Bigass #Teen #Blowjob | O4: https://thumb.tapecontent.net/thumb/vxMBoKwORPCJpO/2BRjoBbq3xFZgVp.jpg
A5: Addison Vodka - 47359261 - Onlyfans.jpg | B5: {New} | C5: =LEFT(A5,FIND("-",A5)-1) -> Addison Vodka | D5: https://doodstream.com/d/4a8gvzx3zlsj/ | E5: https://lulustream.com/d/kxhttf9kyu59 | F5: =IFERROR(__xludf.DUMMYFUNCTION("""https://streamtape.com/v/""& REGEXEXTRACT(O5,""/thumb/([^/]+)/"")& ""/""&K5"),"https://streamtape.com/v/BqxkdYRDDbsyz2o/47359261") -> https://streamtape.com/v/BqxkdYRDDbsyz2o/47359261 | G5: =_xludf.CONCAT(D5,K5) -> #NAME? | H5: =IFERROR(__xludf.DUMMYFUNCTION("IFERROR(SUBSTITUTE(SUBSTITUTE(REGEXEXTRACT(A5, ""[^-]+- [^-]+- [^-]+ - (.+?)\.jpg""), "".jpg"", """"), ""-"", "", ""), """")"),"") | J5: =IF(B5="{New}", "(" & YEAR(TODAY()) & ")", "") -> (2026) | K5: =MID(A5,FIND("-",A5)+2,8) -> 47359261 | L5: #Hardcore, #Piss, #Teen, #Blowjob | M5: =IFERROR(__xludf.DUMMYFUNCTION("TRIM( REGEXREPLACE( TEXTJOIN("" "", TRUE, B5, C5, embaralharLinks(E5,F5,G5), H5, """", J5, N5, ""#RIPNSFW"" ), "",\s*"", "" "") )"),"{New} Addison Vodka https://streamtape.com/v/BqxkdYRDDbsyz2o/47359261 https://lulustream.com/d/kxhttf9kyu59 https://doodstream.com/d/4a8gvzx3zlsj/47359261 (2026) #Hardcore #Piss #Teen #Blowjob #RIPNSFW") -> {New} Addison Vodka https://streamtape.com/v/BqxkdYRDDbsyz2o/47359261 https://lulustream.com/d/kxhttf9kyu59 https://doodstream.com/d/4a8gvzx3zlsj/47359261 (2026) #Hardcore #Piss #Teen #Blowjob #RIPNSFW | N5: #Hardcore #Piss #Teen #Blowjob | O5: https://thumb.tapecontent.net/thumb/BqxkdYRDDbsyz2o/j6LxxemxeMSzZpJ.jpg
A6: Adriana Chechik - 30957968 - ripnsfw.com.jpg | B6: {New} | C6: =LEFT(A6,FIND("-",A6)-1) -> Adriana Chechik | D6: https://doodstream.com/d/iw4qvl4tyiu4/ | E6: https://lulustream.com/d/qplmyjy6230d | F6: =IFERROR(__xludf.DUMMYFUNCTION("""https://streamtape.com/v/""& REGEXEXTRACT(O6,""/thumb/([^/]+)/"")& ""/""&K6"),"https://streamtape.com/v/ZDyaom2V3mUqb6B/30957968") -> https://streamtape.com/v/ZDyaom2V3mUqb6B/30957968 | G6: =_xludf.CONCAT(D6,K6) -> #NAME? | H6: =IFERROR(__xludf.DUMMYFUNCTION("IFERROR(SUBSTITUTE(SUBSTITUTE(REGEXEXTRACT(A6, ""[^-]+- [^-]+- [^-]+ - (.+?)\.jpg""), "".jpg"", """"), ""-"", "", ""), """")"),"") | J6: =IF(B6="{New}", "(" & YEAR(TODAY()) & ")", "") -> (2026) | K6: =MID(A6,FIND("-",A6)+2,8) -> 30957968 | L6: #MILF, #Hardcore, #Porn, #Teen, #Blowjob, #Deepthroat, #Facial | M6: =IFERROR(__xludf.DUMMYFUNCTION("TRIM( REGEXREPLACE( TEXTJOIN("" "", TRUE, B6, C6, embaralharLinks(E6,F6,G6), H6, """", J6, N6, ""#RIPNSFW"" ), "",\s*"", "" "") )"),"{New} Adriana Chechik https://streamtape.com/v/ZDyaom2V3mUqb6B/30957968 https://doodstream.com/d/iw4qvl4tyiu4/30957968 https://lulustream.com/d/qplmyjy6230d (2026) #MILF #Hardcore #Porn #Teen #Blowjob #Deepthroat #RIPNSFW") -> {New} Adriana Chechik https://streamtape.com/v/ZDyaom2V3mUqb6B/30957968 https://doodstream.com/d/iw4qvl4tyiu4/30957968 https://lulustream.com/d/qplmyjy6230d (2026) #MILF #Hardcore #Porn #Teen #Blowjob #Deepthroat #RIPNSFW | N6: #MILF #Hardcore #Porn #Teen #Blowjob #Deepthroat | O6: https://thumb.tapecontent.net/thumb/ZDyaom2V3mUqb6B/KG0MmJW2wBIaZJ.jpg
A7: Adriana Chechik - 34528255 - Onlyfans - Kimmy Granger.jpg | B7: {New} | C7: =LEFT(A7,FIND("-",A7)-1) -> Adriana Chechik | D7: https://doodstream.com/d/oynafg1m456b/ | E7: https://lulustream.com/d/m4q76vm6vdz8 | F7: =IFERROR(__xludf.DUMMYFUNCTION("""https://streamtape.com/v/""& REGEXEXTRACT(O7,""/thumb/([^/]+)/"")& ""/""&K7"),"https://streamtape.com/v/4XpOdzjQ9DUKRDX/34528255") -> https://streamtape.com/v/4XpOdzjQ9DUKRDX/34528255 | G7: =_xludf.CONCAT(D7,K7) -> #NAME? | H7: =IFERROR(__xludf.DUMMYFUNCTION("IFERROR(SUBSTITUTE(SUBSTITUTE(REGEXEXTRACT(A7, ""[^-]+- [^-]+- [^-]+ - (.+?)\.jpg""), "".jpg"", """"), ""-"", "", ""), """")"),"Kimmy Granger") -> Kimmy Granger | J7: =IF(B7="{New}", "(" & YEAR(TODAY()) & ")", "") -> (2026) | K7: =MID(A7,FIND("-",A7)+2,8) -> 34528255 | L7: #MILF, #BigTits, #Hardcore, #Threesome | M7: =IFERROR(__xludf.DUMMYFUNCTION("TRIM( REGEXREPLACE( TEXTJOIN("" "", TRUE, B7, C7, embaralharLinks(E7,F7,G7), H7, """", J7, N7, ""#RIPNSFW"" ), "",\s*"", "" "") )"),"{New} Adriana Chechik https://streamtape.com/v/4XpOdzjQ9DUKRDX/34528255 https://lulustream.com/d/m4q76vm6vdz8 https://doodstream.com/d/oynafg1m456b/34528255 Kimmy Granger (2026) #MILF #BigTits #Hardcore #Threesome #RIPNSFW") -> {New} Adriana Chechik https://streamtape.com/v/4XpOdzjQ9DUKRDX/34528255 https://lulustream.com/d/m4q76vm6vdz8 https://doodstream.com/d/oynafg1m456b/34528255 Kimmy Granger (2026) #MILF #BigTits #Hardcore #Threesome #RIPNSFW | N7: #MILF #BigTits #Hardcore #Threesome | O7: https://thumb.tapecontent.net/thumb/4XpOdzjQ9DUKRDX/96VmPDbdL6HOQm.jpg
A8: Adriana Chechik - 51420656 - Onlyfans.jpg | B8: {New} | C8: =LEFT(A8,FIND("-",A8)-1) -> Adriana Chechik | D8: https://doodstream.com/d/grn1adoy03ts/ | E8: https://lulustream.com/d/ru8de3p9o4cs | F8: =IFERROR(__xludf.DUMMYFUNCTION("""https://streamtape.com/v/""& REGEXEXTRACT(O8,""/thumb/([^/]+)/"")& ""/""&K8"),"https://streamtape.com/v/ykK684mJqei1Akw/51420656") -> https://streamtape.com/v/ykK684mJqei1Akw/51420656 | G8: =_xludf.CONCAT(D8,K8) -> #NAME? | H8: =IFERROR(__xludf.DUMMYFUNCTION("IFERROR(SUBSTITUTE(SUBSTITUTE(REGEXEXTRACT(A8, ""[^-]+- [^-]+- [^-]+ - (.+?)\.jpg""), "".jpg"", """"), ""-"", "", ""), """")"),"") | J8: =IF(B8="{New}", "(" & YEAR(TODAY()) & ")", "") -> (2026) | K8: =MID(A8,FIND("-",A8)+2,8) -> 51420656 | L8: #MILF, #Blowjob, #Amateur, #Hotwife | M8: =IFERROR(__xludf.DUMMYFUNCTION("TRIM( REGEXREPLACE( TEXTJOIN("" "", TRUE, B8, C8, embaralharLinks(E8,F8,G8), H8, """", J8, N8, ""#RIPNSFW"" ), "",\s*"", "" "") )"),"{New} Adriana Chechik https://lulustream.com/d/ru8de3p9o4cs https://streamtape.com/v/ykK684mJqei1Akw/51420656 https://doodstream.com/d/grn1adoy03ts/51420656 (2026) #MILF #Blowjob #Amateur #Hotwife #RIPNSFW") -> {New} Adriana Chechik https://lulustream.com/d/ru8de3p9o4cs https://streamtape.com/v/ykK684mJqei1Akw/51420656 https://doodstream.com/d/grn1adoy03ts/51420656 (2026) #MILF #Blowjob #Amateur #Hotwife #RIPNSFW | N8: #MILF #Blowjob #Amateur #Hotwife | O8: https://thumb.tapecontent.net/thumb/ykK684mJqei1Akw/7KVQkKK7d7UAq09.jpg
A9: Adriana Chechik - 59972113 - Tushy.jpg | B9: {New} | C9: =LEFT(A9,FIND("-",A9)-1) -> Adriana Chechik | D9: https://doodstream.com/d/asxvhhf5pzc0/ | E9: https://lulustream.com/d/yddqas6660uo | F9: =IFERROR(__xludf.DUMMYFUNCTION("""https://streamtape.com/v/""& REGEXEXTRACT(O9,""/thumb/([^/]+)/"")& ""/""&K9"),"https://streamtape.com/v/pgbZd2DxRBsryWr/59972113") -> https://streamtape.com/v/pgbZd2DxRBsryWr/59972113 | G9: =_xludf.CONCAT(D9,K9) -> #NAME? | H9: =IFERROR(__xludf.DUMMYFUNCTION("IFERROR(SUBSTITUTE(SUBSTITUTE(REGEXEXTRACT(A9, ""[^-]+- [^-]+- [^-]+ - (.+?)\.jpg""), "".jpg"", """"), ""-"", "", ""), """")"),"") | J9: =IF(B9="{New}", "(" & YEAR(TODAY()) & ")", "") -> (2026) | K9: =MID(A9,FIND("-",A9)+2,8) -> 59972113 | L9: #Anal, #MILF, #Hardcore, #Porn, #Blowjob, #Hotwife, #Deepthroat, #Facial | M9: =IFERROR(__xludf.DUMMYFUNCTION("TRIM( REGEXREPLACE( TEXTJOIN("" "", TRUE, B9, C9, embaralharLinks(E9,F9,G9), H9, """", J9, N9, ""#RIPNSFW"" ), "",\s*"", "" "") )"),"{New} Adriana Chechik https://doodstream.com/d/asxvhhf5pzc0/59972113 https://streamtape.com/v/pgbZd2DxRBsryWr/59972113 https://lulustream.com/d/yddqas6660uo (2026) #Anal #MILF #Hardcore #Porn #Blowjob #RIPNSFW") -> {New} Adriana Chechik https://doodstream.com/d/asxvhhf5pzc0/59972113 https://streamtape.com/v/pgbZd2DxRBsryWr/59972113 https://lulustream.com/d/yddqas6660uo (2026) #Anal #MILF #Hardcore #Porn #Blowjob #RIPNSFW | N9: #Anal #MILF #Hardcore #Porn #Blowjob | O9: https://thumb.tapecontent.net/thumb/pgbZd2DxRBsryWr/dQgqZOVw2rhkk0Q.jpg
A10: Adriana Chechik - 60434496 - ripnsfw.com - Lena the plug.jpg | B10: {New} | C10: =LEFT(A10,FIND("-",A10)-1) -> Adriana Chechik | D10: https://doodstream.com/d/6nkhfsi7h1rn/ | E10: https://lulustream.com/d/10eqg0h4m2mj | F10: =IFERROR(__xludf.DUMMYFUNCTION("""https://streamtape.com/v/""& REGEXEXTRACT(O10,""/thumb/([^/]+)/"")& ""/""&K10"),"https://streamtape.com/v/pY1k88evJpSWml/60434496") -> https://streamtape.com/v/pY1k88evJpSWml/60434496 | G10: =_xludf.CONCAT(D10,K10) -> #NAME? | H10: =IFERROR(__xludf.DUMMYFUNCTION("IFERROR(SUBSTITUTE(SUBSTITUTE(REGEXEXTRACT(A10, ""[^-]+- [^-]+- [^-]+ - (.+?)\.jpg""), "".jpg"", """"), ""-"", "", ""), """")"),"Lena the plug") -> Lena the plug | J10: =IF(B10="{New}", "(" & YEAR(TODAY()) & ")", "") -> (2026) | K10: =MID(A10,FIND("-",A10)+2,8) -> 60434496 | L10: #MILF, #BigTits, #Hardcore, #Threesome, #Bigass, #Blowjob, #Amateur, #Facial | M10: =IFERROR(__xludf.DUMMYFUNCTION("TRIM( REGEXREPLACE( TEXTJOIN("" "", TRUE, B10, C10, embaralharLinks(E10,F10,G10), H10, """", J10, N10, ""#RIPNSFW"" ), "",\s*"", "" "") )"),"{New} Adriana Chechik https://doodstream.com/d/6nkhfsi7h1rn/60434496 https://lulustream.com/d/10eqg0h4m2mj https://streamtape.com/v/pY1k88evJpSWml/60434496 Lena the plug (2026) #MILF #BigTits #Hardcore #Threesome #Bigass #Blowjob #Amateur #Facial #RIPNSFW") -> {New} Adriana Chechik https://doodstream.com/d/6nkhfsi7h1rn/60434496 https://lulustream.com/d/10eqg0h4m2mj https://streamtape.com/v/pY1k88evJpSWml/60434496 Lena the plug (2026) #MILF #BigTits #Hardcore #Threesome #Bigass #Blowjob #Amateur #Facial #RIPNSFW | N10: #MILF #BigTits #Hardcore #Threesome #Bigass #Blowjob #Amateur #Facial | O10: https://thumb.tapecontent.net/thumb/pY1k88evJpSWml/agQWmyXolkFx1g2.jpg
A11: Adriana Chechik - 69701197 - Onlyfans.jpg | B11: {New} | C11: =LEFT(A11,FIND("-",A11)-1) -> Adriana Chechik | D11: https://doodstream.com/d/z5rv7rlp8qpb/ | E11: https://lulustream.com/d/fsgom1xzeb29 | F11: =IFERROR(__xludf.DUMMYFUNCTION("""https://streamtape.com/v/""& REGEXEXTRACT(O11,""/thumb/([^/]+)/"")& ""/""&K11"),"https://streamtape.com/v/Qe7Rr1aepztrOa/69701197") -> https://streamtape.com/v/Qe7Rr1aepztrOa/69701197 | G11: =_xludf.CONCAT(D11,K11) -> #NAME? | H11: =IFERROR(__xludf.DUMMYFUNCTION("IFERROR(SUBSTITUTE(SUBSTITUTE(REGEXEXTRACT(A11, ""[^-]+- [^-]+- [^-]+ - (.+?)\.jpg""), "".jpg"", """"), ""-"", "", ""), """")"),"") | J11: =IF(B11="{New}", "(" & YEAR(TODAY()) & ")", "") -> (2026) | K11: =MID(A11,FIND("-",A11)+2,8) -> 69701197 | L11: #Anal, #MILF, #BigTits, #Hardcore | M11: =IFERROR(__xludf.DUMMYFUNCTION("TRIM( REGEXREPLACE( TEXTJOIN("" "", TRUE, B11, C11, embaralharLinks(E11,F11,G11), H11, """", J11, N11, ""#RIPNSFW"" ), "",\s*"", "" "") )"),"{New} Adriana Chechik https://doodstream.com/d/z5rv7rlp8qpb/69701197 https://streamtape.com/v/Qe7Rr1aepztrOa/69701197 https://lulustream.com/d/fsgom1xzeb29 (2026) #Anal #MILF #BigTits #Hardcore #RIPNSFW") -> {New} Adriana Chechik https://doodstream.com/d/z5rv7rlp8qpb/69701197 https://streamtape.com/v/Qe7Rr1aepztrOa/69701197 https://lulustream.com/d/fsgom1xzeb29 (2026) #Anal #MILF #BigTits #Hardcore #RIPNSFW | N11: #Anal #MILF #BigTits #Hardcore | O11: https://thumb.tapecontent.net/thumb/Qe7Rr1aepztrOa/GwKkDa7RBDUYmW.jpg
A12: Adriana Chechik - 78872640 - Onlyfans.jpg | B12: {New} | C12: =LEFT(A12,FIND("-",A12)-1) -> Adriana Chechik | D12: https://doodstream.com/d/4890kzdzvprn/ | E12: https://lulustream.com/d/p5yx1cweyqbf | F12: =IFERROR(__xludf.DUMMYFUNCTION("""https://streamtape.com/v/""& REGEXEXTRACT(O12,""/thumb/([^/]+)/"")& ""/""&K12"),"https://streamtape.com/v/6XqxDbemVJiv1o/78872640") -> https://streamtape.com/v/6XqxDbemVJiv1o/78872640 | G12: =_xludf.CONCAT(D12,K12) -> #NAME? | H12: =IFERROR(__xludf.DUMMYFUNCTION("IFERROR(SUBSTITUTE(SUBSTITUTE(REGEXEXTRACT(A12, ""[^-]+- [^-]+- [^-]+ - (.+?)\.jpg""), "".jpg"", """"), ""-"", "", ""), """")"),"") | J12: =IF(B12="{New}", "(" & YEAR(TODAY()) & ")", "") -> (2026) | K12: =MID(A12,FIND("-",A12)+2,8) -> 78872640 | L12: #Anal, #MILF, #BigTits, #Hardcore | M12: =IFERROR(__xludf.DUMMYFUNCTION("TRIM( REGEXREPLACE( TEXTJOIN("" "", TRUE, B12, C12, embaralharLinks(E12,F12,G12), H12, """", J12, N12, ""#RIPNSFW"" ), "",\s*"", "" "") )"),"{New} Adriana Chechik https://lulustream.com/d/p5yx1cweyqbf https://doodstream.com/d/4890kzdzvprn/78872640 https://streamtape.com/v/6XqxDbemVJiv1o/78872640 (2026) #Anal #MILF #BigTits #Hardcore #RIPNSFW") -> {New} Adriana Chechik https://lulustream.com/d/p5yx1cweyqbf https://doodstream.com/d/4890kzdzvprn/78872640 https://streamtape.com/v/6XqxDbemVJiv1o/78872640 (2026) #Anal #MILF #BigTits #Hardcore #RIPNSFW | N12: #Anal #MILF #BigTits #Hardcore | O12: https://thumb.tapecontent.net/thumb/6XqxDbemVJiv1o/reoqlexm7jhMV4.jpg
A13: Alanna Pow - 15841633 - Onlyfans.jpg | B13: {New} | C13: =LEFT(A13,FIND("-",A13)-1) -> Alanna Pow | D13: https://doodstream.com/d/ccfg6h6q5f0r/ | E13: https://lulustream.com/d/2qov6vidlykk | F13: =IFERROR(__xludf.DUMMYFUNCTION("""https://streamtape.com/v/""& REGEXEXTRACT(O13,""/thumb/([^/]+)/"")& ""/""&K13"),"https://streamtape.com/v/Xya4vBeZkmUXy1/15841633") -> https://streamtape.com/v/Xya4vBeZkmUXy1/15841633 | G13: =_xludf.CONCAT(D13,K13) -> #NAME? | H13: =IFERROR(__xludf.DUMMYFUNCTION("IFERROR(SUBSTITUTE(SUBSTITUTE(REGEXEXTRACT(A13, ""[^-]+- [^-]+- [^-]+ - (.+?)\.jpg""), "".jpg"", """"), ""-"", "", ""), """")"),"") | J13: =IF(B13="{New}", "(" & YEAR(TODAY()) & ")", "") -> (2026) | K13: =MID(A13,FIND("-",A13)+2,8) -> 15841633 | L13: #BigTits, #Bigass, #Teen, #Blowjob | M13: =IFERROR(__xludf.DUMMYFUNCTION("TRIM( REGEXREPLACE( TEXTJOIN("" "", TRUE, B13, C13, embaralharLinks(E13,F13,G13), H13, """", J13, N13, ""#RIPNSFW"" ), "",\s*"", "" "") )"),"{New} Alanna Pow https://streamtape.com/v/Xya4vBeZkmUXy1/15841633 https://doodstream.com/d/ccfg6h6q5f0r/15841633 https://lulustream.com/d/2qov6vidlykk (2026) #BigTits #Bigass #Teen #Blowjob #RIPNSFW") -> {New} Alanna Pow https://streamtape.com/v/Xya4vBeZkmUXy1/15841633 https://doodstream.com/d/ccfg6h6q5f0r/15841633 https://lulustream.com/d/2qov6vidlykk (2026) #BigTits #Bigass #Teen #Blowjob #RIPNSFW | N13: #BigTits #Bigass #Teen #Blowjob | O13: https://thumb.tapecontent.net/thumb/Xya4vBeZkmUXy1/6bwPYBJApQf918g.jpg
A14: Alanna Pow - 17406382 - ripnsfw.com.jpg | B14: {New} | C14: =LEFT(A14,FIND("-",A14)-1) -> Alanna Pow | D14: https://doodstream.com/d/rp7w5wlhyopr/ | E14: https://lulustream.com/d/34biz1fgg2q9 | F14: =IFERROR(__xludf.DUMMYFUNCTION("""https://streamtape.com/v/""& REGEXEXTRACT(O14,""/thumb/([^/]+)/"")& ""/""&K14"),"https://streamtape.com/v/GXeoyO3391C9lP/17406382") -> https://streamtape.com/v/GXeoyO3391C9lP/17406382 | G14: =_xludf.CONCAT(D14,K14) -> #NAME? | H14: =IFERROR(__xludf.DUMMYFUNCTION("IFERROR(SUBSTITUTE(SUBSTITUTE(REGEXEXTRACT(A14, ""[^-]+- [^-]+- [^-]+ - (.+?)\.jpg""), "".jpg"", """"), ""-"", "", ""), """")"),"") | J14: =IF(B14="{New}", "(" & YEAR(TODAY()) & ")", "") -> (2026) | K14: =MID(A14,FIND("-",A14)+2,8) -> 17406382 | L14: #BigTits, #Creampie, #Hardcore, #Bigass, #Teen, #Blowjob, #Amateur, #Deepthroat, #Blonde, #Facial | M14: =IFERROR(__xludf.DUMMYFUNCTION("TRIM( REGEXREPLACE( TEXTJOIN("" "", TRUE, B14, C14, embaralharLinks(E14,F14,G14), H14, """", J14, N14, ""#RIPNSFW"" ), "",\s*"", "" "") )"),"{New} Alanna Pow https://doodstream.com/d/rp7w5wlhyopr/17406382 https://lulustream.com/d/34biz1fgg2q9 https://streamtape.com/v/GXeoyO3391C9lP/17406382 (2026) #BigTits #Creampie #Hardcore #Bigass #Teen #RIPNSFW") -> {New} Alanna Pow https://doodstream.com/d/rp7w5wlhyopr/17406382 https://lulustream.com/d/34biz1fgg2q9 https://streamtape.com/v/GXeoyO3391C9lP/17406382 (2026) #BigTits #Creampie #Hardcore #Bigass #Teen #RIPNSFW | N14: #BigTits #Creampie #Hardcore #Bigass #Teen | O14: https://thumb.tapecontent.net/thumb/GXeoyO3391C9lP/1WgdG8GLJ4se21k.jpg
A15: Alanna Pow - 17563322 - Onlyfans.jpg | B15: {New} | C15: =LEFT(A15,FIND("-",A15)-1) -> Alanna Pow | D15: https://doodstream.com/d/rfcpsjxxrvei/ | E15: https://lulustream.com/d/jgnj29xlndop | F15: =IFERROR(__xludf.DUMMYFUNCTION("""https://streamtape.com/v/""& REGEXEXTRACT(O15,""/thumb/([^/]+)/"")& ""/""&K15"),"https://streamtape.com/v/0dWRBVbB2JFbxa3/17563322") -> https://streamtape.com/v/0dWRBVbB2JFbxa3/17563322 | G15: =_xludf.CONCAT(D15,K15) -> #NAME? | H15: =IFERROR(__xludf.DUMMYFUNCTION("IFERROR(SUBSTITUTE(SUBSTITUTE(REGEXEXTRACT(A15, ""[^-]+- [^-]+- [^-]+ - (.+?)\.jpg""), "".jpg"", """"), ""-"", "", ""), """")"),"") | J15: =IF(B15="{New}", "(" & YEAR(TODAY()) & ")", "") -> (2026) | K15: =MID(A15,FIND("-",A15)+2,8) -> 17563322 | L15: #BigTits, #Bigass, #Teen, #Blowjob | M15: =IFERROR(__xludf.DUMMYFUNCTION("TRIM( REGEXREPLACE( TEXTJOIN("" "", TRUE, B15, C15, embaralharLinks(E15,F15,G15), H15, """", J15, N15, ""#RIPNSFW"" ), "",\s*"", "" "") )"),"{New} Alanna Pow https://lulustream.com/d/jgnj29xlndop https://doodstream.com/d/rfcpsjxxrvei/17563322 https://streamtape.com/v/0dWRBVbB2JFbxa3/17563322 (2026) #BigTits #Bigass #Teen #Blowjob #RIPNSFW") -> {New} Alanna Pow https://lulustream.com/d/jgnj29xlndop https://doodstream.com/d/rfcpsjxxrvei/17563322 https://streamtape.com/v/0dWRBVbB2JFbxa3/17563322 (2026) #BigTits #Bigass #Teen #Blowjob #RIPNSFW | N15: #BigTits #Bigass #Teen #Blowjob | O15: https://thumb.tapecontent.net/thumb/0dWRBVbB2JFbxa3/AkBRyDODRXcXqQ1.jpg
A16: Alanna Pow - 18308184 - Onlyfans.jpg | B16: {New} | C16: =LEFT(A16,FIND("-",A16)-1) -> Alanna Pow | D16: https://doodstream.com/d/s14c1x3qpqjj/ | E16: https://lulustream.com/d/6k39hcuucj6f | F16: =IFERROR(__xludf.DUMMYFUNCTION("""https://streamtape.com/v/""& REGEXEXTRACT(O16,""/thumb/([^/]+)/"")& ""/""&K16"),"https://streamtape.com/v/GbZdrYRVbYH17zq/18308184") -> https://streamtape.com/v/GbZdrYRVbYH17zq/18308184 | G16: =_xludf.CONCAT(D16,K16) -> #NAME? | H16: =IFERROR(__xludf.DUMMYFUNCTION("IFERROR(SUBSTITUTE(SUBSTITUTE(REGEXEXTRACT(A16, ""[^-]+- [^-]+- [^-]+ - (.+?)\.jpg""), "".jpg"", """"), ""-"", "", ""), """")"),"") | J16: =IF(B16="{New}", "(" & YEAR(TODAY()) & ")", "") -> (2026) | K16: =MID(A16,FIND("-",A16)+2,8) -> 18308184 | L16: #BigTits, #Bigass, #Teen, #Blowjob, #Amateur, #Facial, #Blonde, #Deepthroat | M16: =IFERROR(__xludf.DUMMYFUNCTION("TRIM( REGEXREPLACE( TEXTJOIN("" "", TRUE, B16, C16, embaralharLinks(E16,F16,G16), H16, """", J16, N16, ""#RIPNSFW"" ), "",\s*"", "" "") )"),"{New} Alanna Pow https://streamtape.com/v/GbZdrYRVbYH17zq/18308184 https://lulustream.com/d/6k39hcuucj6f https://doodstream.com/d/s14c1x3qpqjj/18308184 (2026) #BigTits #Bigass #Teen #Blowjob #Amateur #Facial #Blonde #Deepthroat #RIPNSFW") -> {New} Alanna Pow https://streamtape.com/v/GbZdrYRVbYH17zq/18308184 https://lulustream.com/d/6k39hcuucj6f https://doodstream.com/d/s14c1x3qpqjj/18308184 (2026) #BigTits #Bigass #Teen #Blowjob #Amateur #Facial #Blonde #Deepthroat #RIPNSFW | N16: #BigTits #Bigass #Teen #Blowjob #Amateur #Facial #Blonde #Deepthroat | O16: https://thumb.tapecontent.net/thumb/GbZdrYRVbYH17zq/eYj8LQrY3dIY4l3.jpg
A17: Alanna Pow - 19034023 - Onlyfans.jpg | B17: {New} | C17: =LEFT(A17,FIND("-",A17)-1) -> Alanna Pow | D17: https://doodstream.com/d/vaflm6b6anmg/ | E17: https://lulustream.com/d/akzepx724qwo | F17: =IFERROR(__xludf.DUMMYFUNCTION("""https://streamtape.com/v/""& REGEXEXTRACT(O17,""/thumb/([^/]+)/"")& ""/""&K17"),"https://streamtape.com/v/D02L1469leskeMZ/19034023") -> https://streamtape.com/v/D02L1469leskeMZ/19034023 | G17: =_xludf.CONCAT(D17,K17) -> #NAME? | H17: =IFERROR(__xludf.DUMMYFUNCTION("IFERROR(SUBSTITUTE(SUBSTITUTE(REGEXEXTRACT(A17, ""[^-]+- [^-]+- [^-]+ - (.+?)\.jpg""), "".jpg"", """"), ""-"", "", ""), """")"),"") | J17: =IF(B17="{New}", "(" & YEAR(TODAY()) & ")", "") -> (2026) | K17: =MID(A17,FIND("-",A17)+2,8) -> 19034023 | L17: #BigTits, #Bigass, #Teen, #Blowjob | M17: =IFERROR(__xludf.DUMMYFUNCTION("TRIM( REGEXREPLACE( TEXTJOIN("" "", TRUE, B17, C17, embaralharLinks(E17,F17,G17), H17, """", J17, N17, ""#RIPNSFW"" ), "",\s*"", "" "") )"),"#ERROR!") -> #ERROR! | N17: #BigTits #Bigass #Teen #Blowjob | O17: https://thumb.tapecontent.net/thumb/D02L1469leskeMZ/QWmv9ADy9Wh0Q7y.jpg
A18: Alanna Pow - 22226111 - Onlyfans.jpg | B18: {New} | C18: =LEFT(A18,FIND("-",A18)-1) -> Alanna Pow | D18: https://doodstream.com/d/u4x7onq939v2/ | E18: https://lulustream.com/d/9g5xi6j2k5ss | F18: =IFERROR(__xludf.DUMMYFUNCTION("""https://streamtape.com/v/""& REGEXEXTRACT(O18,""/thumb/([^/]+)/"")& ""/""&K18"),"https://streamtape.com/v/3Gg2r6MJLMflOz/22226111") -> https://streamtape.com/v/3Gg2r6MJLMflOz/22226111 | G18: =_xludf.CONCAT(D18,K18) -> #NAME? | H18: =IFERROR(__xludf.DUMMYFUNCTION("IFERROR(SUBSTITUTE(SUBSTITUTE(REGEXEXTRACT(A18, ""[^-]+- [^-]+- [^-]+ - (.+?)\.jpg""), "".jpg"", """"), ""-"", "", ""), """")"),"") | J18: =IF(B18="{New}", "(" & YEAR(TODAY()) & ")", "") -> (2026) | K18: =MID(A18,FIND("-",A18)+2,8) -> 22226111 | L18: #BigTits, #Creampie, #Hardcore, #Bigass | M18: =IFERROR(__xludf.DUMMYFUNCTION("TRIM( REGEXREPLACE( TEXTJOIN("" "", TRUE, B18, C18, embaralharLinks(E18,F18,G18), H18, """", J18, N18, ""#RIPNSFW"" ), "",\s*"", "" "") )"),"{New} Alanna Pow https://lulustream.com/d/9g5xi6j2k5ss https://doodstream.com/d/u4x7onq939v2/22226111 https://streamtape.com/v/3Gg2r6MJLMflOz/22226111 (2026) #BigTits #Creampie #Hardcore #Bigass #RIPNSFW") -> {New} Alanna Pow https://lulustream.com/d/9g5xi6j2k5ss https://doodstream.com/d/u4x7onq939v2/22226111 https://streamtape.com/v/3Gg2r6MJLMflOz/22226111 (2026) #BigTits #Creampie #Hardcore #Bigass #RIPNSFW | N18: #BigTits #Creampie #Hardcore #Bigass | O18: https://thumb.tapecontent.net/thumb/3Gg2r6MJLMflOz/wdKwAAPWewFJXy7.jpg
A19: Alanna Pow - 25567227 - Onlyfans.jpg | B19: {New} | C19: =LEFT(A19,FIND("-",A19)-1) -> Alanna Pow | D19: https://doodstream.com/d/q3xj05tknxyh/ | E19: https://lulustream.com/d/3dajng3aeqm0 | F19: =IFERROR(__xludf.DUMMYFUNCTION("""https://streamtape.com/v/""& REGEXEXTRACT(O19,""/thumb/([^/]+)/"")& ""/""&K19"),"https://streamtape.com/v/KeZoqGMBWxt0kkb/25567227") -> https://streamtape.com/v/KeZoqGMBWxt0kkb/25567227 | G19: =_xludf.CONCAT(D19,K19) -> #NAME? | H19: =IFERROR(__xludf.DUMMYFUNCTION("IFERROR(SUBSTITUTE(SUBSTITUTE(REGEXEXTRACT(A19, ""[^-]+- [^-]+- [^-]+ - (.+?)\.jpg""), "".jpg"", """"), ""-"", "", ""), """")"),"") | J19: =IF(B19="{New}", "(" & YEAR(TODAY()) & ")", "") -> (2026) | K19: =MID(A19,FIND("-",A19)+2,8) -> 25567227 | L19: #BigTits, #Bigass, #Teen, #Blowjob | M19: =IFERROR(__xludf.DUMMYFUNCTION("TRIM( REGEXREPLACE( TEXTJOIN("" "", TRUE, B19, C19, embaralharLinks(E19,F19,G19), H19, """", J19, N19, ""#RIPNSFW"" ), "",\s*"", "" "") )"),"{New} Alanna Pow https://streamtape.com/v/KeZoqGMBWxt0kkb/25567227 https://doodstream.com/d/q3xj05tknxyh/25567227 https://lulustream.com/d/3dajng3aeqm0 (2026) #BigTits #Bigass #Teen #Blowjob #RIPNSFW") -> {New} Alanna Pow https://streamtape.com/v/KeZoqGMBWxt0kkb/25567227 https://doodstream.com/d/q3xj05tknxyh/25567227 https://lulustream.com/d/3dajng3aeqm0 (2026) #BigTits #Bigass #Teen #Blowjob #RIPNSFW | N19: #BigTits #Bigass #Teen #Blowjob | O19: https://thumb.tapecontent.net/thumb/KeZoqGMBWxt0kkb/Rk0KGb79q9cdVRK.jpg
A20: Alanna Pow - 26155010 - MCF.jpg | B20: {New} | C20: =LEFT(A20,FIND("-",A20)-1) -> Alanna Pow | D20: https://doodstream.com/d/ztvzkgn3o0cf/ | E20: https://lulustream.com/d/670hw3e5b3mo | F20: =IFERROR(__xludf.DUMMYFUNCTION("""https://streamtape.com/v/""& REGEXEXTRACT(O20,""/thumb/([^/]+)/"")& ""/""&K20"),"https://streamtape.com/v/mrm67xrV8oTbKpV/26155010") -> https://streamtape.com/v/mrm67xrV8oTbKpV/26155010 | G20: =_xludf.CONCAT(D20,K20) -> #NAME? | H20: =IFERROR(__xludf.DUMMYFUNCTION("IFERROR(SUBSTITUTE(SUBSTITUTE(REGEXEXTRACT(A20, ""[^-]+- [^-]+- [^-]+ - (.+?)\.jpg""), "".jpg"", """"), ""-"", "", ""), """")"),"") | J20: =IF(B20="{New}", "(" & YEAR(TODAY()) & ")", "") -> (2026) | K20: =MID(A20,FIND("-",A20)+2,8) -> 26155010 | L20: #BigTits, #MILF, #Hardcore, #Bigass | M20: =IFERROR(__xludf.DUMMYFUNCTION("TRIM( REGEXREPLACE( TEXTJOIN("" "", TRUE, B20, C20, embaralharLinks(E20,F20,G20), H20, """", J20, N20, ""#RIPNSFW"" ), "",\s*"", "" "") )"),"{New} Alanna Pow https://doodstream.com/d/ztvzkgn3o0cf/26155010 https://streamtape.com/v/mrm67xrV8oTbKpV/26155010 https://lulustream.com/d/670hw3e5b3mo (2026) #BigTits #MILF #Hardcore #Bigass #RIPNSFW") -> {New} Alanna Pow https://doodstream.com/d/ztvzkgn3o0cf/26155010 https://streamtape.com/v/mrm67xrV8oTbKpV/26155010 https://lulustream.com/d/670hw3e5b3mo (2026) #BigTits #MILF #Hardcore #Bigass #RIPNSFW | N20: #BigTits #MILF #Hardcore #Bigass | O20: https://thumb.tapecontent.net/thumb/mrm67xrV8oTbKpV/PJKqaQdowpUbDB.jpg
A21: Alanna Pow - 27269863 - Onlyfans.jpg | B21: {New} | C21: =LEFT(A21,FIND("-",A21)-1) -> Alanna Pow | D21: https://doodstream.com/d/tsuzf5cud37n/ | E21: https://lulustream.com/d/k1yvixzldcw8 | F21: =IFERROR(__xludf.DUMMYFUNCTION("""https://streamtape.com/v/""& REGEXEXTRACT(O21,""/thumb/([^/]+)/"")& ""/""&K21"),"https://streamtape.com/v/92x72B1oVpT6AY/27269863") -> https://streamtape.com/v/92x72B1oVpT6AY/27269863 | G21: =_xludf.CONCAT(D21,K21) -> #NAME? | H21: =IFERROR(__xludf.DUMMYFUNCTION("IFERROR(SUBSTITUTE(SUBSTITUTE(REGEXEXTRACT(A21, ""[^-]+- [^-]+- [^-]+ - (.+?)\.jpg""), "".jpg"", """"), ""-"", "", ""), """")"),"") | J21: =IF(B21="{New}", "(" & YEAR(TODAY()) & ")", "") -> (2026) | K21: =MID(A21,FIND("-",A21)+2,8) -> 27269863 | L21: #BigTits, #Bigass, #Teen, #Blowjob | M21: =IFERROR(__xludf.DUMMYFUNCTION("TRIM( REGEXREPLACE( TEXTJOIN("" "", TRUE, B21, C21, embaralharLinks(E21,F21,G21), H21, """", J21, N21, ""#RIPNSFW"" ), "",\s*"", "" "") )"),"{New} Alanna Pow https://lulustream.com/d/k1yvixzldcw8 https://doodstream.com/d/tsuzf5cud37n/27269863 https://streamtape.com/v/92x72B1oVpT6AY/27269863 (2026) #BigTits #Bigass #Teen #Blowjob #RIPNSFW") -> {New} Alanna Pow https://lulustream.com/d/k1yvixzldcw8 https://doodstream.com/d/tsuzf5cud37n/27269863 https://streamtape.com/v/92x72B1oVpT6AY/27269863 (2026) #BigTits #Bigass #Teen #Blowjob #RIPNSFW | N21: #BigTits #Bigass #Teen #Blowjob | O21: https://thumb.tapecontent.net/thumb/92x72B1oVpT6AY/meo1A4eaMduk48.jpg
A22: Alanna Pow - 37317864 - Onlyfans.jpg | B22: {New} | C22: =LEFT(A22,FIND("-",A22)-1) -> Alanna Pow | D22: https://doodstream.com/d/90kstdunkxjq/ | E22: https://lulustream.com/d/agigw3u8dcg1 | F22: =IFERROR(__xludf.DUMMYFUNCTION("""https://streamtape.com/v/""& REGEXEXTRACT(O22,""/thumb/([^/]+)/"")& ""/""&K22"),"https://streamtape.com/v/aYzDX643xqhx1Z9/37317864") -> https://streamtape.com/v/aYzDX643xqhx1Z9/37317864 | G22: =_xludf.CONCAT(D22,K22) -> #NAME? | H22: =IFERROR(__xludf.DUMMYFUNCTION("IFERROR(SUBSTITUTE(SUBSTITUTE(REGEXEXTRACT(A22, ""[^-]+- [^-]+- [^-]+ - (.+?)\.jpg""), "".jpg"", """"), ""-"", "", ""), """")"),"") | J22: =IF(B22="{New}", "(" & YEAR(TODAY()) & ")", "") -> (2026) | K22: =MID(A22,FIND("-",A22)+2,8) -> 37317864 | L22: #MILF, #BigTits, #Hardcore, #Bigass | M22: =IFERROR(__xludf.DUMMYFUNCTION("TRIM( REGEXREPLACE( TEXTJOIN("" "", TRUE, B22, C22, embaralharLinks(E22,F22,G22), H22, """", J22, N22, ""#RIPNSFW"" ), "",\s*"", "" "") )"),"{New} Alanna Pow https://doodstream.com/d/90kstdunkxjq/37317864 https://streamtape.com/v/aYzDX643xqhx1Z9/37317864 https://lulustream.com/d/agigw3u8dcg1 (2026) #MILF #BigTits #Hardcore #Bigass #RIPNSFW") -> {New} Alanna Pow https://doodstream.com/d/90kstdunkxjq/37317864 https://streamtape.com/v/aYzDX643xqhx1Z9/37317864 https://lulustream.com/d/agigw3u8dcg1 (2026) #MILF #BigTits #Hardcore #Bigass #RIPNSFW | N22: #MILF #BigTits #Hardcore #Bigass | O22: https://thumb.tapecontent.net/thumb/aYzDX643xqhx1Z9/LdrLOVlWlBIRddm.jpg
A23: Alanna Pow - 37925673 - ripnsfw.com.jpg | B23: {New} | C23: =LEFT(A23,FIND("-",A23)-1) -> Alanna Pow | D23: https://doodstream.com/d/ipv0wku6p57d/ | E23: https://lulustream.com/d/o4mlp4evm3wy | F23: =IFERROR(__xludf.DUMMYFUNCTION("""https://streamtape.com/v/""& REGEXEXTRACT(O23,""/thumb/([^/]+)/"")& ""/""&K23"),"https://streamtape.com/v/w7vRjBeyaZfJ88W/37925673") -> https://streamtape.com/v/w7vRjBeyaZfJ88W/37925673 | G23: =_xludf.CONCAT(D23,K23) -> #NAME? | H23: =IFERROR(__xludf.DUMMYFUNCTION("IFERROR(SUBSTITUTE(SUBSTITUTE(REGEXEXTRACT(A23, ""[^-]+- [^-]+- [^-]+ - (.+?)\.jpg""), "".jpg"", """"), ""-"", "", ""), """")"),"") | J23: =IF(B23="{New}", "(" & YEAR(TODAY()) & ")", "") -> (2026) | K23: =MID(A23,FIND("-",A23)+2,8) -> 37925673 | L23: #MILF, #BigTits, #Hardcore, #Black, #Interracial, #Bigass, #Teen, #Blowjob, #Amateur, #Blonde, #Deepthroat | M23: =IFERROR(__xludf.DUMMYFUNCTION("TRIM( REGEXREPLACE( TEXTJOIN("" "", TRUE, B23, C23, embaralharLinks(E23,F23,G23), H23, """", J23, N23, ""#RIPNSFW"" ), "",\s*"", "" "") )"),"{New} Alanna Pow https://streamtape.com/v/w7vRjBeyaZfJ88W/37925673 https://doodstream.com/d/ipv0wku6p57d/37925673 https://lulustream.com/d/o4mlp4evm3wy (2026) #MILF #BigTits #Hardcore #Black #Interracial #Bigass #Teen #Blowjob #Amateur #RIPNSFW") -> {New} Alanna Pow https://streamtape.com/v/w7vRjBeyaZfJ88W/37925673 https://doodstream.com/d/ipv0wku6p57d/37925673 https://lulustream.com/d/o4mlp4evm3wy (2026) #MILF #BigTits #Hardcore #Black #Interracial #Bigass #Teen #Blowjob #Amateur #RIPNSFW | N23: #MILF #BigTits #Hardcore #Black #Interracial #Bigass #Teen #Blowjob #Amateur | O23: https://thumb.tapecontent.net/thumb/w7vRjBeyaZfJ88W/j7RqjJP3zPIzWKK.jpg
A24: Alanna Pow - 38181644 - Onlyfans.jpg | B24: {New} | C24: =LEFT(A24,FIND("-",A24)-1) -> Alanna Pow | D24: https://doodstream.com/d/25o4hpmqzo7z/ | E24: https://lulustream.com/d/0heg056665vg | F24: =IFERROR(__xludf.DUMMYFUNCTION("""https://streamtape.com/v/""& REGEXEXTRACT(O24,""/thumb/([^/]+)/"")& ""/""&K24"),"https://streamtape.com/v/XgRG33lLAZsgpv/38181644") -> https://streamtape.com/v/XgRG33lLAZsgpv/38181644 | G24: =_xludf.CONCAT(D24,K24) -> #NAME? | H24: =IFERROR(__xludf.DUMMYFUNCTION("IFERROR(SUBSTITUTE(SUBSTITUTE(REGEXEXTRACT(A24, ""[^-]+- [^-]+- [^-]+ - (.+?)\.jpg""), "".jpg"", """"), ""-"", "", ""), """")"),"") | J24: =IF(B24="{New}", "(" & YEAR(TODAY()) & ")", "") -> (2026) | K24: =MID(A24,FIND("-",A24)+2,8) -> 38181644 | L24: #BigTits, #Bigass, #Teen, #Blowjob | M24: =IFERROR(__xludf.DUMMYFUNCTION("TRIM( REGEXREPLACE( TEXTJOIN("" "", TRUE, B24, C24, embaralharLinks(E24,F24,G24), H24, """", J24, N24, ""#RIPNSFW"" ), "",\s*"", "" "") )"),"{New} Alanna Pow https://doodstream.com/d/25o4hpmqzo7z/38181644 https://streamtape.com/v/XgRG33lLAZsgpv/38181644 https://lulustream.com/d/0heg056665vg (2026) #BigTits #Bigass #Teen #Blowjob #RIPNSFW") -> {New} Alanna Pow https://doodstream.com/d/25o4hpmqzo7z/38181644 https://streamtape.com/v/XgRG33lLAZsgpv/38181644 https://lulustream.com/d/0heg056665vg (2026) #BigTits #Bigass #Teen #Blowjob #RIPNSFW | N24: #BigTits #Bigass #Teen #Blowjob | O24: https://thumb.tapecontent.net/thumb/XgRG33lLAZsgpv/oQrqAmlO8kUJVAk.jpg
A25: Alanna Pow - 38679952 - XVRED.jpg | B25: {New} | C25: =LEFT(A25,FIND("-",A25)-1) -> Alanna Pow | D25: https://doodstream.com/d/0it670gat4vl/ | E25: https://lulustream.com/d/mrnyv6gmxp1f | F25: =IFERROR(__xludf.DUMMYFUNCTION("""https://streamtape.com/v/""& REGEXEXTRACT(O25,""/thumb/([^/]+)/"")& ""/""&K25"),"https://streamtape.com/v/yAwVJpaXxzI1W4A/38679952") -> https://streamtape.com/v/yAwVJpaXxzI1W4A/38679952 | G25: =_xludf.CONCAT(D25,K25) -> #NAME? | H25: =IFERROR(__xludf.DUMMYFUNCTION("IFERROR(SUBSTITUTE(SUBSTITUTE(REGEXEXTRACT(A25, ""[^-]+- [^-]+- [^-]+ - (.+?)\.jpg""), "".jpg"", """"), ""-"", "", ""), """")"),"") | J25: =IF(B25="{New}", "(" & YEAR(TODAY()) & ")", "") -> (2026) | K25: =MID(A25,FIND("-",A25)+2,8) -> 38679952 | L25: #BigTits, #Bigass, #Teen, #Blowjob | M25: =IFERROR(__xludf.DUMMYFUNCTION("TRIM( REGEXREPLACE( TEXTJOIN("" "", TRUE, B25, C25, embaralharLinks(E25,F25,G25), H25, """", J25, N25, ""#RIPNSFW"" ), "",\s*"", "" "") )"),"{New} Alanna Pow https://lulustream.com/d/mrnyv6gmxp1f https://doodstream.com/d/0it670gat4vl/38679952 https://streamtape.com/v/yAwVJpaXxzI1W4A/38679952 (2026) #BigTits #Bigass #Teen #Blowjob #RIPNSFW") -> {New} Alanna Pow https://lulustream.com/d/mrnyv6gmxp1f https://doodstream.com/d/0it670gat4vl/38679952 https://streamtape.com/v/yAwVJpaXxzI1W4A/38679952 (2026) #BigTits #Bigass #Teen #Blowjob #RIPNSFW | N25: #BigTits #Bigass #Teen #Blowjob | O25: https://thumb.tapecontent.net/thumb/yAwVJpaXxzI1W4A/Pr8jvQYaR7c0QGx.jpg
A26: Alanna Pow - 54503023 - Onlyfans.jpg | B26: {New} | C26: =LEFT(A26,FIND("-",A26)-1) -> Alanna Pow | D26: https://doodstream.com/d/jmcjx10qnbrc/ | E26: https://lulustream.com/d/wz3eb9qspm5d | F26: =IFERROR(__xludf.DUMMYFUNCTION("""https://streamtape.com/v/""& REGEXEXTRACT(O26,""/thumb/([^/]+)/"")& ""/""&K26"),"https://streamtape.com/v/JX7xbVjV1ysZ6r/54503023") -> https://streamtape.com/v/JX7xbVjV1ysZ6r/54503023 | G26: =_xludf.CONCAT(D26,K26) -> #NAME? | H26: =IFERROR(__xludf.DUMMYFUNCTION("IFERROR(SUBSTITUTE(SUBSTITUTE(REGEXEXTRACT(A26, ""[^-]+- [^-]+- [^-]+ - (.+?)\.jpg""), "".jpg"", """"), ""-"", "", ""), """")"),"") | J26: =IF(B26="{New}", "(" & YEAR(TODAY()) & ")", "") -> (2026) | K26: =MID(A26,FIND("-",A26)+2,8) -> 54503023 | L26: #BigTits, #Bigass, #Teen, #Blowjob | M26: =IFERROR(__xludf.DUMMYFUNCTION("TRIM( REGEXREPLACE( TEXTJOIN("" "", TRUE, B26, C26, embaralharLinks(E26,F26,G26), H26, """", J26, N26, ""#RIPNSFW"" ), "",\s*"", "" "") )"),"{New} Alanna Pow https://doodstream.com/d/jmcjx10qnbrc/54503023 https://lulustream.com/d/wz3eb9qspm5d https://streamtape.com/v/JX7xbVjV1ysZ6r/54503023 (2026) #BigTits #Bigass #Teen #Blowjob #RIPNSFW") -> {New} Alanna Pow https://doodstream.com/d/jmcjx10qnbrc/54503023 https://lulustream.com/d/wz3eb9qspm5d https://streamtape.com/v/JX7xbVjV1ysZ6r/54503023 (2026) #BigTits #Bigass #Teen #Blowjob #RIPNSFW | N26: #BigTits #Bigass #Teen #Blowjob | O26: https://thumb.tapecontent.net/thumb/JX7xbVjV1ysZ6r/JAyAM87bZ0FjBGO.jpg
A27: Alanna Pow - 54606458 - Onlyfans.jpg | B27: {New} | C27: =LEFT(A27,FIND("-",A27)-1) -> Alanna Pow | D27: https://doodstream.com/d/xxlwjgm20d7x/ | E27: https://lulustream.com/d/qnootfyydx1n | F27: =IFERROR(__xludf.DUMMYFUNCTION("""https://streamtape.com/v/""& REGEXEXTRACT(O27,""/thumb/([^/]+)/"")& ""/""&K27"),"https://streamtape.com/v/082qbZXgjAcb1Db/54606458") -> https://streamtape.com/v/082qbZXgjAcb1Db/54606458 | G27: =_xludf.CONCAT(D27,K27) -> #NAME? | H27: =IFERROR(__xludf.DUMMYFUNCTION("IFERROR(SUBSTITUTE(SUBSTITUTE(REGEXEXTRACT(A27, ""[^-]+- [^-]+- [^-]+ - (.+?)\.jpg""), "".jpg"", """"), ""-"", "", ""), """")"),"") | J27: =IF(B27="{New}", "(" & YEAR(TODAY()) & ")", "") -> (2026) | K27: =MID(A27,FIND("-",A27)+2,8) -> 54606458 | L27: #BigTits, #Bigass, #Teen, #Blowjob | M27: =IFERROR(__xludf.DUMMYFUNCTION("TRIM( REGEXREPLACE( TEXTJOIN("" "", TRUE, B27, C27, embaralharLinks(E27,F27,G27), H27, """", J27, N27, ""#RIPNSFW"" ), "",\s*"", "" "") )"),"{New} Alanna Pow https://doodstream.com/d/xxlwjgm20d7x/54606458 https://lulustream.com/d/qnootfyydx1n https://streamtape.com/v/082qbZXgjAcb1Db/54606458 (2026) #BigTits #Bigass #Teen #Blowjob #RIPNSFW") -> {New} Alanna Pow https://doodstream.com/d/xxlwjgm20d7x/54606458 https://lulustream.com/d/qnootfyydx1n https://streamtape.com/v/082qbZXgjAcb1Db/54606458 (2026) #BigTits #Bigass #Teen #Blowjob #RIPNSFW | N27: #BigTits #Bigass #Teen #Blowjob | O27: https://thumb.tapecontent.net/thumb/082qbZXgjAcb1Db/kv0KeD31rRHy1l.jpg
A28: Alanna Pow - 61011031 - ripnsfw.com - Lena the plug.jpg | B28: {New} | C28: =LEFT(A28,FIND("-",A28)-1) -> Alanna Pow | D28: https://doodstream.com/d/t4cw7igq24kl/ | E28: https://lulustream.com/d/nd8bgmvefkyv | F28: =IFERROR(__xludf.DUMMYFUNCTION("""https://streamtape.com/v/""& REGEXEXTRACT(O28,""/thumb/([^/]+)/"")& ""/""&K28"),"https://streamtape.com/v/ykJapV24dRF1DBD/61011031") -> https://streamtape.com/v/ykJapV24dRF1DBD/61011031 | G28: =_xludf.CONCAT(D28,K28) -> #NAME? | H28: =IFERROR(__xludf.DUMMYFUNCTION("IFERROR(SUBSTITUTE(SUBSTITUTE(REGEXEXTRACT(A28, ""[^-]+- [^-]+- [^-]+ - (.+?)\.jpg""), "".jpg"", """"), ""-"", "", ""), """")"),"Lena the plug") -> Lena the plug | J28: =IF(B28="{New}", "(" & YEAR(TODAY()) & ")", "") -> (2026) | K28: =MID(A28,FIND("-",A28)+2,8) -> 61011031 | L28: #MILF, #BigTits, #Hardcore, #Threesome, #Bigass, #Teen, #Blowjob, #Amateur, #Hotwife, #Blonde, #Facial | M28: =IFERROR(__xludf.DUMMYFUNCTION("TRIM( REGEXREPLACE( TEXTJOIN("" "", TRUE, B28, C28, embaralharLinks(E28,F28,G28), H28, """", J28, N28, ""#RIPNSFW"" ), "",\s*"", "" "") )"),"{New} Alanna Pow https://streamtape.com/v/ykJapV24dRF1DBD/61011031 https://doodstream.com/d/t4cw7igq24kl/61011031 https://lulustream.com/d/nd8bgmvefkyv Lena the plug (2026) #MILF #BigTits #Hardcore #Threesome #Bigass #Teen #Blowjob #RIPNSFW") -> {New} Alanna Pow https://streamtape.com/v/ykJapV24dRF1DBD/61011031 https://doodstream.com/d/t4cw7igq24kl/61011031 https://lulustream.com/d/nd8bgmvefkyv Lena the plug (2026) #MILF #BigTits #Hardcore #Threesome #Bigass #Teen #Blowjob #RIPNSFW | N28: #MILF #BigTits #Hardcore #Threesome #Bigass #Teen #Blowjob | O28: https://thumb.tapecontent.net/thumb/ykJapV24dRF1DBD/wrAOBrQOg0HJqrV.jpg
A29: Alanna Pow - 62436241 - ripnsfw.com.jpg | B29: {New} | C29: =LEFT(A29,FIND("-",A29)-1) -> Alanna Pow | D29: https://doodstream.com/d/pgk741qzghdi/ | E29: https://lulustream.com/d/6kinxp49ummh | F29: =IFERROR(__xludf.DUMMYFUNCTION("""https://streamtape.com/v/""& REGEXEXTRACT(O29,""/thumb/([^/]+)/"")& ""/""&K29"),"https://streamtape.com/v/oMbdogoq7PcJzVR/62436241") -> https://streamtape.com/v/oMbdogoq7PcJzVR/62436241 | G29: =_xludf.CONCAT(D29,K29) -> #NAME? | H29: =IFERROR(__xludf.DUMMYFUNCTION("IFERROR(SUBSTITUTE(SUBSTITUTE(REGEXEXTRACT(A29, ""[^-]+- [^-]+- [^-]+ - (.+?)\.jpg""), "".jpg"", """"), ""-"", "", ""), """")"),"") | J29: =IF(B29="{New}", "(" & YEAR(TODAY()) & ")", "") -> (2026) | K29: =MID(A29,FIND("-",A29)+2,8) -> 62436241 | L29: #BigTits, #Hardcore, #Bigass, #Teen, #Blowjob, #Amateur, #Deepthroat, #Blonde, #Facial | M29: =IFERROR(__xludf.DUMMYFUNCTION("TRIM( REGEXREPLACE( TEXTJOIN("" "", TRUE, B29, C29, embaralharLinks(E29,F29,G29), H29, """", J29, N29, ""#RIPNSFW"" ), "",\s*"", "" "") )"),"{New} Alanna Pow https://lulustream.com/d/6kinxp49ummh https://streamtape.com/v/oMbdogoq7PcJzVR/62436241 https://doodstream.com/d/pgk741qzghdi/62436241 (2026) #BigTits #Hardcore #Bigass #Teen #Blowjob #RIPNSFW") -> {New} Alanna Pow https://lulustream.com/d/6kinxp49ummh https://streamtape.com/v/oMbdogoq7PcJzVR/62436241 https://doodstream.com/d/pgk741qzghdi/62436241 (2026) #BigTits #Hardcore #Bigass #Teen #Blowjob #RIPNSFW | N29: #BigTits #Hardcore #Bigass #Teen #Blowjob | O29: https://thumb.tapecontent.net/thumb/oMbdogoq7PcJzVR/DAyxqw0ebXskjXd.jpg
A30: Alanna Pow - 62968616 - Onlyfans.jpg | B30: {New} | C30: =LEFT(A30,FIND("-",A30)-1) -> Alanna Pow | D30: https://doodstream.com/d/wg30ws65tlsl/ | E30: https://lulustream.com/d/hq2ek4yamn5m | F30: =IFERROR(__xludf.DUMMYFUNCTION("""https://streamtape.com/v/""& REGEXEXTRACT(O30,""/thumb/([^/]+)/"")& ""/""&K30"),"https://streamtape.com/v/lxyd9VjLZxu7pMQ/62968616") -> https://streamtape.com/v/lxyd9VjLZxu7pMQ/62968616 | G30: =_xludf.CONCAT(D30,K30) -> #NAME? | H30: =IFERROR(__xludf.DUMMYFUNCTION("IFERROR(SUBSTITUTE(SUBSTITUTE(REGEXEXTRACT(A30, ""[^-]+- [^-]+- [^-]+ - (.+?)\.jpg""), "".jpg"", """"), ""-"", "", ""), """")"),"") | J30: =IF(B30="{New}", "(" & YEAR(TODAY()) & ")", "") -> (2026) | K30: =MID(A30,FIND("-",A30)+2,8) -> 62968616 | L30: #BigTits, #Bigass, #Teen, #Blowjob | M30: =IFERROR(__xludf.DUMMYFUNCTION("TRIM( REGEXREPLACE( TEXTJOIN("" "", TRUE, B30, C30, embaralharLinks(E30,F30,G30), H30, """", J30, N30, ""#RIPNSFW"" ), "",\s*"", "" "") )"),"{New} Alanna Pow https://doodstream.com/d/wg30ws65tlsl/62968616 https://streamtape.com/v/lxyd9VjLZxu7pMQ/62968616 https://lulustream.com/d/hq2ek4yamn5m (2026) #BigTits #Bigass #Teen #Blowjob #RIPNSFW") -> {New} Alanna Pow https://doodstream.com/d/wg30ws65tlsl/62968616 https://streamtape.com/v/lxyd9VjLZxu7pMQ/62968616 https://lulustream.com/d/hq2ek4yamn5m (2026) #BigTits #Bigass #Teen #Blowjob #RIPNSFW | N30: #BigTits #Bigass #Teen #Blowjob | O30: https://thumb.tapecontent.net/thumb/lxyd9VjLZxu7pMQ/Q0z3XO7zR9C0x6d.jpg
A31: Alanna Pow - 63393477 - ripnsfw.com.jpg | B31: {New} | C31: =LEFT(A31,FIND("-",A31)-1) -> Alanna Pow | D31: https://doodstream.com/d/5k393rfh3ehj/ | E31: https://lulustream.com/d/7rmboytus18b | F31: =IFERROR(__xludf.DUMMYFUNCTION("""https://streamtape.com/v/""& REGEXEXTRACT(O31,""/thumb/([^/]+)/"")& ""/""&K31"),"https://streamtape.com/v/kDgmb2y6wasO2QL/63393477") -> https://streamtape.com/v/kDgmb2y6wasO2QL/63393477 | G31: =_xludf.CONCAT(D31,K31) -> #NAME? | H31: =IFERROR(__xludf.DUMMYFUNCTION("IFERROR(SUBSTITUTE(SUBSTITUTE(REGEXEXTRACT(A31, ""[^-]+- [^-]+- [^-]+ - (.+?)\.jpg""), "".jpg"", """"), ""-"", "", ""), """")"),"") | J31: =IF(B31="{New}", "(" & YEAR(TODAY()) & ")", "") -> (2026) | K31: =MID(A31,FIND("-",A31)+2,8) -> 63393477 | L31: #BigTits, #Hardcore, #Bigass, #Teen, #Artporn, #Teens, #Amateur, #Deepthroat, #Facial, #Blonde | M31: =IFERROR(__xludf.DUMMYFUNCTION("TRIM( REGEXREPLACE( TEXTJOIN("" "", TRUE, B31, C31, embaralharLinks(E31,F31,G31), H31, """", J31, N31, ""#RIPNSFW"" ), "",\s*"", "" "") )"),"{New} Alanna Pow https://doodstream.com/d/5k393rfh3ehj/63393477 https://lulustream.com/d/7rmboytus18b https://streamtape.com/v/kDgmb2y6wasO2QL/63393477 (2026) #BigTits #Hardcore #Bigass #Teen #Artporn #RIPNSFW") -> {New} Alanna Pow https://doodstream.com/d/5k393rfh3ehj/63393477 https://lulustream.com/d/7rmboytus18b https://streamtape.com/v/kDgmb2y6wasO2QL/63393477 (2026) #BigTits #Hardcore #Bigass #Teen #Artporn #RIPNSFW | N31: #BigTits #Hardcore #Bigass #Teen #Artporn | O31: https://thumb.tapecontent.net/thumb/kDgmb2y6wasO2QL/lwk6LWKJoWiAaa.jpg
A32: Alanna Pow - 65492185 - ripnsfw.com.jpg | B32: {New} | C32: =LEFT(A32,FIND("-",A32)-1) -> Alanna Pow | D32: https://doodstream.com/d/ccukxnfsif65/ | E32: https://lulustream.com/d/eez691u865ep | F32: =IFERROR(__xludf.DUMMYFUNCTION("""https://streamtape.com/v/""& REGEXEXTRACT(O32,""/thumb/([^/]+)/"")& ""/""&K32"),"https://streamtape.com/v/XzXKqJlK3oSDqle/65492185") -> https://streamtape.com/v/XzXKqJlK3oSDqle/65492185 | G32: =_xludf.CONCAT(D32,K32) -> #NAME? | H32: =IFERROR(__xludf.DUMMYFUNCTION("IFERROR(SUBSTITUTE(SUBSTITUTE(REGEXEXTRACT(A32, ""[^-]+- [^-]+- [^-]+ - (.+?)\.jpg""), "".jpg"", """"), ""-"", "", ""), """")"),"") | J32: =IF(B32="{New}", "(" & YEAR(TODAY()) & ")", "") -> (2026) | K32: =MID(A32,FIND("-",A32)+2,8) -> 65492185 | L32: #BigTits, #Hardcore, #Bigass, #Teen, #Blowjob, #Amateur, #Facial, #Blonde | M32: =IFERROR(__xludf.DUMMYFUNCTION("TRIM( REGEXREPLACE( TEXTJOIN("" "", TRUE, B32, C32, embaralharLinks(E32,F32,G32), H32, """", J32, N32, ""#RIPNSFW"" ), "",\s*"", "" "") )"),"{New} Alanna Pow https://doodstream.com/d/ccukxnfsif65/65492185 https://lulustream.com/d/eez691u865ep https://streamtape.com/v/XzXKqJlK3oSDqle/65492185 (2026) #BigTits #Hardcore #Bigass #Teen #Blowjob #Amateur #Facial #RIPNSFW") -> {New} Alanna Pow https://doodstream.com/d/ccukxnfsif65/65492185 https://lulustream.com/d/eez691u865ep https://streamtape.com/v/XzXKqJlK3oSDqle/65492185 (2026) #BigTits #Hardcore #Bigass #Teen #Blowjob #Amateur #Facial #RIPNSFW | N32: #BigTits #Hardcore #Bigass #Teen #Blowjob #Amateur #Facial | O32: https://thumb.tapecontent.net/thumb/XzXKqJlK3oSDqle/bqJdl1meVysRww.jpg
A33: Alanna Pow - 67907097 - ripnsfw.com.jpg | B33: {New} | C33: =LEFT(A33,FIND("-",A33)-1) -> Alanna Pow | D33: https://doodstream.com/d/vr4cu9g6r3bp/ | E33: https://lulustream.com/d/dat15ogft72x | F33: =IFERROR(__xludf.DUMMYFUNCTION("""https://streamtape.com/v/""& REGEXEXTRACT(O33,""/thumb/([^/]+)/"")& ""/""&K33"),"https://streamtape.com/v/Ww1m9vRPK1fqwK/67907097") -> https://streamtape.com/v/Ww1m9vRPK1fqwK/67907097 | G33: =_xludf.CONCAT(D33,K33) -> #NAME? | H33: =IFERROR(__xludf.DUMMYFUNCTION("IFERROR(SUBSTITUTE(SUBSTITUTE(REGEXEXTRACT(A33, ""[^-]+- [^-]+- [^-]+ - (.+?)\.jpg""), "".jpg"", """"), ""-"", "", ""), """")"),"") | J33: =IF(B33="{New}", "(" & YEAR(TODAY()) & ")", "") -> (2026) | K33: =MID(A33,FIND("-",A33)+2,8) -> 67907097 | L33: #BigTits, #Creampie, #Hardcore, #Bigass, #Teen, #Blowjob, #Amateur, #Blonde | M33: =IFERROR(__xludf.DUMMYFUNCTION("TRIM( REGEXREPLACE( TEXTJOIN("" "", TRUE, B33, C33, embaralharLinks(E33,F33,G33), H33, """", J33, N33, ""#RIPNSFW"" ), "",\s*"", "" "") )"),"{New} Alanna Pow https://streamtape.com/v/Ww1m9vRPK1fqwK/67907097 https://lulustream.com/d/dat15ogft72x https://doodstream.com/d/vr4cu9g6r3bp/67907097 (2026) #BigTits #Creampie #Hardcore #Bigass #Teen #Blowjob #RIPNSFW") -> {New} Alanna Pow https://streamtape.com/v/Ww1m9vRPK1fqwK/67907097 https://lulustream.com/d/dat15ogft72x https://doodstream.com/d/vr4cu9g6r3bp/67907097 (2026) #BigTits #Creampie #Hardcore #Bigass #Teen #Blowjob #RIPNSFW | N33: #BigTits #Creampie #Hardcore #Bigass #Teen #Blowjob | O33: https://thumb.tapecontent.net/thumb/Ww1m9vRPK1fqwK/WbWPqAZlW2Ub7bG.jpg
A34: Alanna Pow - 69979470 - Onlyfans.jpg | B34: {New} | C34: =LEFT(A34,FIND("-",A34)-1) -> Alanna Pow | D34: https://doodstream.com/d/60ve1m8rumvx/ | E34: https://lulustream.com/d/f7w5iqfwefo5 | F34: =IFERROR(__xludf.DUMMYFUNCTION("""https://streamtape.com/v/""& REGEXEXTRACT(O34,""/thumb/([^/]+)/"")& ""/""&K34"),"https://streamtape.com/v/ZPopRlqxXbCoMB/69979470") -> https://streamtape.com/v/ZPopRlqxXbCoMB/69979470 | G34: =_xludf.CONCAT(D34,K34) -> #NAME? | H34: =IFERROR(__xludf.DUMMYFUNCTION("IFERROR(SUBSTITUTE(SUBSTITUTE(REGEXEXTRACT(A34, ""[^-]+- [^-]+- [^-]+ - (.+?)\.jpg""), "".jpg"", """"), ""-"", "", ""), """")"),"") | J34: =IF(B34="{New}", "(" & YEAR(TODAY()) & ")", "") -> (2026) | K34: =MID(A34,FIND("-",A34)+2,8) -> 69979470 | L34: #BigTits, #Bigass, #Teen, #Blowjob | M34: =IFERROR(__xludf.DUMMYFUNCTION("TRIM( REGEXREPLACE( TEXTJOIN("" "", TRUE, B34, C34, embaralharLinks(E34,F34,G34), H34, """", J34, N34, ""#RIPNSFW"" ), "",\s*"", "" "") )"),"{New} Alanna Pow https://doodstream.com/d/60ve1m8rumvx/69979470 https://lulustream.com/d/f7w5iqfwefo5 https://streamtape.com/v/ZPopRlqxXbCoMB/69979470 (2026) #BigTits #Bigass #Teen #Blowjob #RIPNSFW") -> {New} Alanna Pow https://doodstream.com/d/60ve1m8rumvx/69979470 https://lulustream.com/d/f7w5iqfwefo5 https://streamtape.com/v/ZPopRlqxXbCoMB/69979470 (2026) #BigTits #Bigass #Teen #Blowjob #RIPNSFW | N34: #BigTits #Bigass #Teen #Blowjob | O34: https://thumb.tapecontent.net/thumb/ZPopRlqxXbCoMB/Be9KQBrZvlHyxpq.jpg
A35: Alanna Pow - 71566037 - ripnsfw.com.jpg | B35: {New} | C35: =LEFT(A35,FIND("-",A35)-1) -> Alanna Pow | D35: https://doodstream.com/d/jp88l39qrrxj/ | E35: https://lulustream.com/d/5vxzigynjn98 | F35: =IFERROR(__xludf.DUMMYFUNCTION("""https://streamtape.com/v/""& REGEXEXTRACT(O35,""/thumb/([^/]+)/"")& ""/""&K35"),"https://streamtape.com/v/mgY1oyd4Ogsb3V3/71566037") -> https://streamtape.com/v/mgY1oyd4Ogsb3V3/71566037 | G35: =_xludf.CONCAT(D35,K35) -> #NAME? | H35: =IFERROR(__xludf.DUMMYFUNCTION("IFERROR(SUBSTITUTE(SUBSTITUTE(REGEXEXTRACT(A35, ""[^-]+- [^-]+- [^-]+ - (.+?)\.jpg""), "".jpg"", """"), ""-"", "", ""), """")"),"") | J35: =IF(B35="{New}", "(" & YEAR(TODAY()) & ")", "") -> (2026) | K35: =MID(A35,FIND("-",A35)+2,8) -> 71566037 | L35: #BigTits, #Hardcore, #Bigass, #Teen, #Blowjob, #Amateur, #Blonde | M35: =IFERROR(__xludf.DUMMYFUNCTION("TRIM( REGEXREPLACE( TEXTJOIN("" "", TRUE, B35, C35, embaralharLinks(E35,F35,G35), H35, """", J35, N35, ""#RIPNSFW"" ), "",\s*"", "" "") )"),"{New} Alanna Pow https://doodstream.com/d/jp88l39qrrxj/71566037 https://lulustream.com/d/5vxzigynjn98 https://streamtape.com/v/mgY1oyd4Ogsb3V3/71566037 (2026) #BigTits #Hardcore #Bigass #Teen #Blowjob #Amateur #RIPNSFW") -> {New} Alanna Pow https://doodstream.com/d/jp88l39qrrxj/71566037 https://lulustream.com/d/5vxzigynjn98 https://streamtape.com/v/mgY1oyd4Ogsb3V3/71566037 (2026) #BigTits #Hardcore #Bigass #Teen #Blowjob #Amateur #RIPNSFW | N35: #BigTits #Hardcore #Bigass #Teen #Blowjob #Amateur | O35: https://thumb.tapecontent.net/thumb/mgY1oyd4Ogsb3V3/ZoJ1yQQ4mXfwq8.jpg
A36: Alanna Pow - 72639064 - ripnsfw.com.jpg | B36: {New} | C36: =LEFT(A36,FIND("-",A36)-1) -> Alanna Pow | D36: https://doodstream.com/d/fks6fq0j3ayc/ | E36: https://lulustream.com/d/repjq78qcmaw | F36: =IFERROR(__xludf.DUMMYFUNCTION("""https://streamtape.com/v/""& REGEXEXTRACT(O36,""/thumb/([^/]+)/"")& ""/""&K36"),"https://streamtape.com/v/3ab30K1bWySDZD/72639064") -> https://streamtape.com/v/3ab30K1bWySDZD/72639064 | G36: =_xludf.CONCAT(D36,K36) -> #NAME? | H36: =IFERROR(__xludf.DUMMYFUNCTION("IFERROR(SUBSTITUTE(SUBSTITUTE(REGEXEXTRACT(A36, ""[^-]+- [^-]+- [^-]+ - (.+?)\.jpg""), "".jpg"", """"), ""-"", "", ""), """")"),"") | J36: =IF(B36="{New}", "(" & YEAR(TODAY()) & ")", "") -> (2026) | K36: =MID(A36,FIND("-",A36)+2,8) -> 72639064 | L36: #BigTits, #Hardcore, #Bigass, #Teen, #Blowjob, #Amateur, #Deepthroat, #Blonde | M36: =IFERROR(__xludf.DUMMYFUNCTION("TRIM( REGEXREPLACE( TEXTJOIN("" "", TRUE, B36, C36, embaralharLinks(E36,F36,G36), H36, """", J36, N36, ""#RIPNSFW"" ), "",\s*"", "" "") )"),"{New} Alanna Pow https://streamtape.com/v/3ab30K1bWySDZD/72639064 https://lulustream.com/d/repjq78qcmaw https://doodstream.com/d/fks6fq0j3ayc/72639064 (2026) #BigTits #Hardcore #Bigass #Teen #Blowjob #RIPNSFW") -> {New} Alanna Pow https://streamtape.com/v/3ab30K1bWySDZD/72639064 https://lulustream.com/d/repjq78qcmaw https://doodstream.com/d/fks6fq0j3ayc/72639064 (2026) #BigTits #Hardcore #Bigass #Teen #Blowjob #RIPNSFW | N36: #BigTits #Hardcore #Bigass #Teen #Blowjob | O36: https://thumb.tapecontent.net/thumb/3ab30K1bWySDZD/GbAxAmP74DuYKl.jpg
A37: Alanna Pow - 72645909 - Onlyfans.jpg | B37: {New} | C37: =LEFT(A37,FIND("-",A37)-1) -> Alanna Pow | D37: https://doodstream.com/d/skr79wkziy0d/ | E37: https://lulustream.com/d/5gyjbuhx4h2c | F37: =IFERROR(__xludf.DUMMYFUNCTION("""https://streamtape.com/v/""& REGEXEXTRACT(O37,""/thumb/([^/]+)/"")& ""/""&K37"),"https://streamtape.com/v/e3Dva9KD1OTmwe/72645909") -> https://streamtape.com/v/e3Dva9KD1OTmwe/72645909 | G37: =_xludf.CONCAT(D37,K37) -> #NAME? | H37: =IFERROR(__xludf.DUMMYFUNCTION("IFERROR(SUBSTITUTE(SUBSTITUTE(REGEXEXTRACT(A37, ""[^-]+- [^-]+- [^-]+ - (.+?)\.jpg""), "".jpg"", """"), ""-"", "", ""), """")"),"") | J37: =IF(B37="{New}", "(" & YEAR(TODAY()) & ")", "") -> (2026) | K37: =MID(A37,FIND("-",A37)+2,8) -> 72645909 | L37: #BigTits, #Bigass, #Teen, #Blowjob | M37: =IFERROR(__xludf.DUMMYFUNCTION("TRIM( REGEXREPLACE( TEXTJOIN("" "", TRUE, B37, C37, embaralharLinks(E37,F37,G37), H37, """", J37, N37, ""#RIPNSFW"" ), "",\s*"", "" "") )"),"{New} Alanna Pow https://lulustream.com/d/5gyjbuhx4h2c https://streamtape.com/v/e3Dva9KD1OTmwe/72645909 https://doodstream.com/d/skr79wkziy0d/72645909 (2026) #BigTits #Bigass #Teen #Blowjob #RIPNSFW") -> {New} Alanna Pow https://lulustream.com/d/5gyjbuhx4h2c https://streamtape.com/v/e3Dva9KD1OTmwe/72645909 https://doodstream.com/d/skr79wkziy0d/72645909 (2026) #BigTits #Bigass #Teen #Blowjob #RIPNSFW | N37: #BigTits #Bigass #Teen #Blowjob | O37: https://thumb.tapecontent.net/thumb/e3Dva9KD1OTmwe/grYOky9DV7UGv6.jpg
A38: Alanna Pow - 73449975 - Onlyfans.jpg | B38: {New} | C38: =LEFT(A38,FIND("-",A38)-1) -> Alanna Pow | D38: https://doodstream.com/d/wjk5xqxhiaxc/ | E38: https://lulustream.com/d/ga7di1cb78vv | F38: =IFERROR(__xludf.DUMMYFUNCTION("""https://streamtape.com/v/""& REGEXEXTRACT(O38,""/thumb/([^/]+)/"")& ""/""&K38"),"https://streamtape.com/v/PLxK7p2l9JS0QvK/73449975") -> https://streamtape.com/v/PLxK7p2l9JS0QvK/73449975 | G38: =_xludf.CONCAT(D38,K38) -> #NAME? | H38: =IFERROR(__xludf.DUMMYFUNCTION("IFERROR(SUBSTITUTE(SUBSTITUTE(REGEXEXTRACT(A38, ""[^-]+- [^-]+- [^-]+ - (.+?)\.jpg""), "".jpg"", """"), ""-"", "", ""), """")"),"") | J38: =IF(B38="{New}", "(" & YEAR(TODAY()) & ")", "") -> (2026) | K38: =MID(A38,FIND("-",A38)+2,8) -> 73449975 | L38: #BigTits, #Hardcore, #Bigass, #Teen | M38: =IFERROR(__xludf.DUMMYFUNCTION("TRIM( REGEXREPLACE( TEXTJOIN("" "", TRUE, B38, C38, embaralharLinks(E38,F38,G38), H38, """", J38, N38, ""#RIPNSFW"" ), "",\s*"", "" "") )"),"{New} Alanna Pow https://doodstream.com/d/wjk5xqxhiaxc/73449975 https://streamtape.com/v/PLxK7p2l9JS0QvK/73449975 https://lulustream.com/d/ga7di1cb78vv (2026) #BigTits #Hardcore #Bigass #Teen #RIPNSFW") -> {New} Alanna Pow https://doodstream.com/d/wjk5xqxhiaxc/73449975 https://streamtape.com/v/PLxK7p2l9JS0QvK/73449975 https://lulustream.com/d/ga7di1cb78vv (2026) #BigTits #Hardcore #Bigass #Teen #RIPNSFW | N38: #BigTits #Hardcore #Bigass #Teen | O38: https://thumb.tapecontent.net/thumb/PLxK7p2l9JS0QvK/XoR2BOm6vZuDjqw.jpg
A39: Alanna Pow - 77110509 - ripnsfw.com.jpg | B39: {New} | C39: =LEFT(A39,FIND("-",A39)-1) -> Alanna Pow | D39: https://doodstream.com/d/lo75arpa05jl/ | E39: https://lulustream.com/d/h3ip8zl4hjvi | F39: =IFERROR(__xludf.DUMMYFUNCTION("""https://streamtape.com/v/""& REGEXEXTRACT(O39,""/thumb/([^/]+)/"")& ""/""&K39"),"https://streamtape.com/v/xowdjrVJGKfkb1A/77110509") -> https://streamtape.com/v/xowdjrVJGKfkb1A/77110509 | G39: =_xludf.CONCAT(D39,K39) -> #NAME? | H39: =IFERROR(__xludf.DUMMYFUNCTION("IFERROR(SUBSTITUTE(SUBSTITUTE(REGEXEXTRACT(A39, ""[^-]+- [^-]+- [^-]+ - (.+?)\.jpg""), "".jpg"", """"), ""-"", "", ""), """")"),"") | J39: =IF(B39="{New}", "(" & YEAR(TODAY()) & ")", "") -> (2026) | K39: =MID(A39,FIND("-",A39)+2,8) -> 77110509 | L39: #BigTits, #Creampie, #Hardcore, #Bigass, #Teen, #Blowjob, #Amateur, #Blonde | M39: =IFERROR(__xludf.DUMMYFUNCTION("TRIM( REGEXREPLACE( TEXTJOIN("" "", TRUE, B39, C39, embaralharLinks(E39,F39,G39), H39, """", J39, N39, ""#RIPNSFW"" ), "",\s*"", "" "") )"),"{New} Alanna Pow https://streamtape.com/v/xowdjrVJGKfkb1A/77110509 https://lulustream.com/d/h3ip8zl4hjvi https://doodstream.com/d/lo75arpa05jl/77110509 (2026) #BigTits #Creampie #Hardcore #Bigass #Teen #Blowjob #Amateur #RIPNSFW") -> {New} Alanna Pow https://streamtape.com/v/xowdjrVJGKfkb1A/77110509 https://lulustream.com/d/h3ip8zl4hjvi https://doodstream.com/d/lo75arpa05jl/77110509 (2026) #BigTits #Creampie #Hardcore #Bigass #Teen #Blowjob #Amateur #RIPNSFW | N39: #BigTits #Creampie #Hardcore #Bigass #Teen #Blowjob #Amateur | O39: https://thumb.tapecontent.net/thumb/xowdjrVJGKfkb1A/l2LmwJD111i7xOV.jpg
A40: Alanna Pow - 77255491 - MLRaw.jpg | B40: {New} | C40: =LEFT(A40,FIND("-",A40)-1) -> Alanna Pow | D40: https://doodstream.com/d/n3cnt005y6co/ | E40: https://lulustream.com/d/n44rz82hlsvm | F40: =IFERROR(__xludf.DUMMYFUNCTION("""https://streamtape.com/v/""& REGEXEXTRACT(O40,""/thumb/([^/]+)/"")& ""/""&K40"),"https://streamtape.com/v/1Amr9mdOkoIewrA/77255491") -> https://streamtape.com/v/1Amr9mdOkoIewrA/77255491 | G40: =_xludf.CONCAT(D40,K40) -> #NAME? | H40: =IFERROR(__xludf.DUMMYFUNCTION("IFERROR(SUBSTITUTE(SUBSTITUTE(REGEXEXTRACT(A40, ""[^-]+- [^-]+- [^-]+ - (.+?)\.jpg""), "".jpg"", """"), ""-"", "", ""), """")"),"") | J40: =IF(B40="{New}", "(" & YEAR(TODAY()) & ")", "") -> (2026) | K40: =MID(A40,FIND("-",A40)+2,8) -> 77255491 | L40: #BigTits, #Bigass, #Teen, #Blowjob | M40: =IFERROR(__xludf.DUMMYFUNCTION("TRIM( REGEXREPLACE( TEXTJOIN("" "", TRUE, B40, C40, embaralharLinks(E40,F40,G40), H40, """", J40, N40, ""#RIPNSFW"" ), "",\s*"", "" "") )"),"{New} Alanna Pow https://doodstream.com/d/n3cnt005y6co/77255491 https://lulustream.com/d/n44rz82hlsvm https://streamtape.com/v/1Amr9mdOkoIewrA/77255491 (2026) #BigTits #Bigass #Teen #Blowjob #RIPNSFW") -> {New} Alanna Pow https://doodstream.com/d/n3cnt005y6co/77255491 https://lulustream.com/d/n44rz82hlsvm https://streamtape.com/v/1Amr9mdOkoIewrA/77255491 (2026) #BigTits #Bigass #Teen #Blowjob #RIPNSFW | N40: #BigTits #Bigass #Teen #Blowjob | O40: https://thumb.tapecontent.net/thumb/1Amr9mdOkoIewrA/jqDYDKlYBBUzyvd.jpg
...

Sheet Página1
A1: POST | B1: THUMB | C1: VIDEO | D1: VIEWS
